Workbook
Name _9_8_2009: #REF!
Name _9_8_2009: #REF!
Name _9_8_2009: #REF!
Name _9_8_2009: #REF!
Name _9_8_2009: #REF!
Name _9_8_2009: #REF!
Name _9_8_2009: #REF!
Name AAAAAA: #REF!
Name AAAAAA: #REF!
Name AAAAAA: #REF!
Name AAAAAA: #REF!
Name AAAAAA: #REF!
Name AAAAAA: #REF!
Name AAAAAA: #REF!
Name Ativo: #REF!
Name Ativo: #REF!
Name Ativo: #REF!
Name Ativo: #REF!
Name Ativo: #REF!
Name Ativo: #REF!
Name Ativo: #REF!
Name CIFRAO: '[1]Entrada Dados - Relatório'!$F$7
Name cpRegistro: "Caixa de texto 111"
Name DRE: #REF!
Name DRE: #REF!
Name DRE: #REF!
Name DRE: #REF!
Name DRE: #REF!
Name DRE: #REF!
Name DRE: #REF!
Name fcaixa: #REF!
Name fcaixa: #REF!
Name fcaixa: #REF!
Name fcaixa: #REF!
Name fcaixa: #REF!
Name fcaixa: #REF!
Name fcaixa: #REF!
Name fimtituloverso: '[2]PTP crerscimento'!#REF!
Name fimtituloverso: '[2]PTP crerscimento'!#REF!
Name fimtituloverso: '[2]PTP crerscimento'!#REF!
Name fimtituloverso: '[2]PTP crerscimento'!#REF!
Name fimtituloverso: '[2]PTP crerscimento'!#REF!
Name fimtituloverso: '[2]PTP crerscimento'!#REF!
Name fimtituloverso: '[2]PTP crerscimento'!#REF!
Name fimverso: '[2]PTP crerscimento'!#REF!
Name fimverso: '[2]PTP crerscimento'!#REF!
Name fimverso: '[2]PTP crerscimento'!#REF!
Name fimverso: '[2]PTP crerscimento'!#REF!
Name fimverso: '[2]PTP crerscimento'!#REF!
Name fimverso: '[2]PTP crerscimento'!#REF!
Name fimverso: '[2]PTP crerscimento'!#REF!
Name IND: #REF!
Name IND: #REF!
Name IND: #REF!
Name IND: #REF!
Name IND: #REF!
Name IND: #REF!
Name IND: #REF!
Name initituloverso: '[2]PTP crerscimento'!#REF!
Name initituloverso: '[2]PTP crerscimento'!#REF!

Sheet OvoTotal
J1: AA | K1: BB | L1: CC | M1: DD | N1: EE | O1: FF | P1: GG | Q1: HH | R1: II | S1: JJ | T1: KK | U1: LL | V1: MM | W1: NN | X1: OO | Y1: PP | Z1: QQ | AA1: RR | AB1: SS | AC1: TT | AD1: UU | AE1: VV | AF1: XX | AG1: YY | AH1: ZZ | AI1: WW | AJ1: AAA | AK1: BBB | AL1: CCC | AM1: DDD | AN1: EEE | AX1: 53
B2: Mês | C2: Ovos Totais | F2: Ovos Totais | G2: Caixas | J2: SJ F1 A 221 R | K2: SJ F1 B 321 R | L2: SJ F1 A 222 R | M2: SJ F1 B 322 R | N2: SJ F2 A 421 R | O2: SJ F2 B 521 R | P2: SJ F2 A 422 R | Q2: SJ F2 B 522 R | R2: SJ F3 820 R | S2: AAA 1 001 | T2: SJ F3 821 R | U2: AAA 1 001 | V2: AAA 1 001 | W2: AAA 1 001 | X2: AAA 1 001 | Y2: AAA 1 001 | Z2: AAA 1 001 | AA2: AAA 1 001 | AB2: AAA 1 001 | AC2: AAA 1 001 | AD2: AAA 1 001 | AE2: AAA 1 001 | AF2: AAA 1 001 | AG2: AAA 1 001 | AH2: AAA 1 001 | AI2: AAA 1 001 | AJ2: AAA 1 001 | AK2: AAA 1 001 | AL2: AAA 1 001 | AM2: AAA 1 001 | AN2: AAA 1 001 | AP2: Total
A3: 1 | B3: Jan | C3: 5550957.2 | E3: 1 | F3: 161423.1 | G3: 448.3975 | I3: 44562 | J3: 40099.213 | K3: 40681.698 | L3: 0 | M3: 0 | N3: 26082.563 | O3: 7701.7293 | P3: 0 | Q3: 0 | R3: 46857.895 | T3: 0 | AP3: 161423.1 | AQ3: 1 | AS3: 161423.1 | AV3: 161423.1 | AW3: 1 | AX3: 1 | AY3: 161423.1 | AZ3: 161423.1
A4: 2 | B4: Fev | C4: 4412117.4 | E4: 2 | F4: 1174989.5 | G4: 3263.8598 | I4: 44563 | J4: 40087.16 | K4: 40669.471 | L4: 0 | M4: 0 | N4: 26072.764 | O4: 11290.607 | P4: 0 | Q4: 0 | R4: 46843.81 | T4: 0 | AP4: 164963.81 | AQ4: 1 | AS4: 326386.91 | AV4: 164963.81 | AW4: 2 | AY4: 164963.81
A5: 3 | B5: Mar | C5: 4582222.7 | E5: 3 | F5: 1319634.5 | G5: 3665.6513 | I5: 44564 | J5: 40075.111 | K5: 40155.305 | L5: 0 | M5: 0 | N5: 26062.968 | O5: 11286.195 | P5: 0 | Q5: 0 | R5: 45946.151 | T5: 0 | AP5: 163525.73 | AQ5: 1 | AS5: 489912.64 | AV5: 163525.73 | AW5: 2 | AY5: 328489.54
A6: 4 | B6: Abr | C6: 4137985.5 | E6: 4 | F6: 1399294.7 | G6: 3886.9298 | I6: 44565 | J6: 39562.278 | K6: 40143.236 | L6: 0 | M6: 0 | N6: 26053.176 | O6: 11281.785 | P6: 0 | Q6: 0 | R6: 45932.341 | T6: 0 | AP6: 162972.81 | AQ6: 1 | AS6: 652885.46 | AV6: 162972.81 | AW6: 2 | AY6: 491462.36
A7: 5 | B7: Mai | C7: 4846295.2 | E7: 5 | F7: 1170375.1 | G7: 3251.0419 | I7: 44566 | J7: 39550.386 | K7: 40131.17 | L7: 0 | M7: 0 | N7: 26043.387 | O7: 11277.377 | P7: 0 | Q7: 0 | R7: 45918.535 | T7: 0 | AP7: 162920.85 | AQ7: 1 | AS7: 815806.31 | AV7: 162920.85 | AW7: 2 | AY7: 654383.21
A8: 6 | B8: Jun | C8: 6068106.8 | E8: 6 | F8: 1132243 | G8: 3145.1196 | I8: 44567 | J8: 39538.499 | K8: 40119.108 | L8: 0 | M8: 0 | N8: 36753.321 | O8: 11272.97 | P8: 0 | Q8: 0 | R8: 45904.733 | T8: 0 | AP8: 173588.63 | AQ8: 1 | AS8: 989394.94 | AV8: 173588.63 | AW8: 2 | AY8: 827971.84
A9: 7 | B9: Jul | C9: 5927701.2 | E9: 7 | F9: 1115836 | G9: 3099.5444 | I9: 44568 | J9: 39526.614 | K9: 40107.049 | L9: 0 | M9: 0 | N9: 36742.274 | O9: 11268.566 | P9: 0 | Q9: 0 | R9: 45890.935 | T9: 0 | AP9: 173535.44 | AQ9: 1 | AS9: 1162930.4 | AV9: 173535.44 | AW9: 2 | AY9: 1001507.3
A10: 8 | B10: Ago | C10: 4271495.8 | E10: 8 | F10: 1099492.9 | G10: 3054.1469 | I10: 44569 | J10: 39514.734 | K10: 40094.994 | L10: 0 | M10: 0 | N10: 36731.23 | O10: 11264.163 | P10: 0 | Q10: 0 | R10: 45877.142 | T10: 0 | AP10: 173482.26 | AQ10: 1 | AS10: 1336412.6 | AV10: 173482.26 | AW10: 2 | AX10: 2 | AY10: 1174989.5 | AZ10: 1174989.5
A11: 9 | B11: Set | C11: 3665565.1 | E11: 9 | F11: 1083213.6 | G11: 3008.9266 | I11: 44570 | J11: 39502.857 | K11: 40082.942 | L11: 0 | M11: 0 | N11: 36720.19 | O11: 26102.174 | P11: 0 | Q11: 0 | R11: 45863.352 | T11: 0 | AP11: 188271.51 | AQ11: 1 | AS11: 1524684.2 | AV11: 188271.51 | AW11: 3 | AY11: 188271.51
A12: 10 | B12: Out | C12: 2546050 | E12: 10 | F12: 1066997.9 | G12: 2963.883 | I12: 44571 | J12: 39490.983 | K12: 39570.008 | L12: 0 | M12: 0 | N12: 36709.153 | O12: 26092.367 | P12: 0 | Q12: 0 | R12: 44967.845 | T12: 0 | AP12: 186830.36 | AQ12: 1 | AS12: 1711514.5 | AV12: 186830.36 | AW12: 3 | AY12: 375101.87
A13: 11 | B13: Nov | C13: 2397169.7 | E13: 11 | F13: 1050845.5 | G13: 2919.0154 | I13: 44572 | J13: 38979.378 | K13: 39558.115 | L13: 0 | M13: 0 | N13: 36698.119 | O13: 26082.563 | P13: 0 | Q13: 0 | R13: 44954.329 | T13: 0 | AP13: 186272.5 | AQ13: 1 | AS13: 1897787 | AV13: 186272.5 | AW13: 3 | AY13: 561374.37
A14: 12 | B14: Dez | C14: 4397917.8 | E14: 12 | F14: 1034756.4 | G14: 2874.3233 | I14: 44573 | J14: 38967.662 | K14: 39546.225 | L14: 0 | M14: 0 | N14: 36687.089 | O14: 26072.764 | P14: 0 | Q14: 0 | R14: 44940.817 | T14: 0 | AP14: 186214.56 | AQ14: 1 | AS14: 2084001.6 | AV14: 186214.56 | AW14: 3 | AY14: 747588.93
B15: 2022 | C15: 52803585 | E15: 13 | F15: 1018730.2 | G15: 2829.8062 | I15: 44574 | J15: 38955.949 | K15: 39534.338 | L15: 0 | M15: 0 | N15: 41260.569 | O15: 26062.968 | P15: 0 | Q15: 0 | R15: 44927.309 | T15: 0 | AP15: 190741.13 | AQ15: 1 | AS15: 2274742.7 | AV15: 190741.13 | AW15: 3 | AY15: 938330.06
E16: 14 | F16: 1002766.9 | G16: 2785.4636 | I16: 44575 | J16: 38944.24 | K16: 39522.455 | L16: 0 | M16: 0 | N16: 41248.167 | O16: 26053.176 | P16: 0 | Q16: 0 | R16: 44913.805 | T16: 0 | AP16: 190681.84 | AQ16: 1 | AS16: 2465424.5 | AV16: 190681.84 | AW16: 3 | AY16: 1129011.9
E17: 15 | F17: 986866.18 | G17: 2741.2949 | I17: 44576 | J17: 38932.535 | K17: 39510.576 | L17: 0 | M17: 0 | N17: 41235.769 | O17: 26043.387 | P17: 0 | Q17: 0 | R17: 44900.305 | T17: 0 | AP17: 190622.57 | AQ17: 1 | AS17: 2656047.1 | AV17: 190622.57 | AW17: 3 | AX17: 3 | AY17: 1319634.5 | AZ17: 1319634.5
E18: 16 | F18: 971027.87 | G18: 2697.2996 | I18: 44577 | J18: 38920.833 | K18: 39498.7 | L18: 0 | M18: 0 | N18: 41223.375 | O18: 36753.321 | P18: 0 | Q18: 0 | R18: 44886.809 | T18: 0 | AP18: 201283.04 | AQ18: 1 | AS18: 2857330.2 | AV18: 201283.04 | AW18: 4 | AY18: 201283.04
E19: 17 | F19: 955251.78 | G19: 2653.4772 | I19: 44578 | J19: 38909.134 | K19: 38986.995 | L19: 0 | M19: 0 | N19: 41210.984 | O19: 36742.274 | P19: 0 | Q19: 0 | R19: 43113.58 | T19: 0 | AP19: 198962.97 | AQ19: 1 | AS19: 3056293.1 | AV19: 198962.97 | AW19: 4 | AY19: 400246.01
E20: 18 | F20: 939537.74 | G20: 2609.8271 | I20: 44579 | J20: 38398.754 | K20: 38975.277 | L20: 0 | M20: 0 | N20: 41198.598 | O20: 36731.23 | P20: 0 | Q20: 0 | R20: 43100.621 | T20: 0 | AP20: 198404.48 | AQ20: 1 | AS20: 3254697.6 | AV20: 198404.48 | AW20: 4 | AY20: 598650.48
E21: 19 | F21: 945551.11 | G21: 2626.5309 | I21: 44580 | J21: 38387.213 | K21: 38963.562 | L21: 0 | M21: 0 | N21: 41186.215 | O21: 36720.19 | P21: 0 | Q21: 0 | R21: 43087.666 | T21: 0 | AP21: 198344.84 | AQ21: 1 | AS21: 3453042.4 | AV21: 198344.84 | AW21: 4 | AY21: 796995.33
E22: 20 | F22: 1016270.1 | G22: 2822.9725 | I22: 44581 | J22: 38375.674 | K22: 38951.85 | L22: 0 | M22: 0 | N22: 43715.43 | O22: 36709.153 | P22: 0 | Q22: 0 | R22: 43074.715 | T22: 0 | AP22: 200826.82 | AQ22: 1 | AS22: 3653869.3 | AV22: 200826.82 | AW22: 4 | AY22: 997822.15
E23: 21 | F23: 1050649.2 | G23: 2918.4701 | I23: 44582 | J23: 38364.14 | K23: 38940.143 | L23: 0 | M23: 0 | N23: 43702.29 | O23: 36698.119 | P23: 0 | Q23: 0 | R23: 43061.768 | T23: 0 | AP23: 200766.46 | AQ23: 1 | AS23: 3854635.7 | AV23: 200766.46 | AW23: 4 | AY23: 1198588.6
E24: 22 | F24: 1242316.9 | G24: 3450.8802 | I24: 44583 | J24: 38352.609 | K24: 38928.438 | L24: 0 | M24: 0 | N24: 43689.155 | O24: 36687.089 | P24: 0 | Q24: 0 | R24: 43048.825 | T24: 0 | AP24: 200706.12 | AQ24: 1 | AS24: 4055341.8 | AV24: 200706.12 | AW24: 4 | AX24: 4 | AY24: 1399294.7 | AZ24: 1399294.7
E25: 23 | F25: 1375974.1 | G25: 3822.1503 | I25: 44584 | J25: 38341.081 | K25: 38916.737 | L25: 0 | M25: 0 | N25: 43676.023 | O25: 41260.569 | P25: 0 | Q25: 0 | R25: 43035.886 | T25: 0 | AP25: 205230.3 | AQ25: 1 | AS25: 4260572.1 | AV25: 205230.3 | AW25: 5 | AY25: 205230.3
E26: 24 | F26: 1423672.9 | G26: 3954.6469 | I26: 44585 | J26: 38329.557 | K26: 38406.258 | L26: 0 | M26: 0 | N26: 43662.895 | O26: 41248.167 | P26: 0 | Q26: 0 | T26: 0 | AP26: 161646.88 | AQ26: 1 | AS26: 4422219 | AV26: 161646.88 | AW26: 5 | AY26: 366877.17
E27: 25 | F27: 1442724.8 | G27: 4007.569 | I27: 44586 | J27: 37820.399 | K27: 38394.714 | L27: 0 | M27: 0 | N27: 43649.771 | O27: 41235.769 | P27: 0 | Q27: 0 | T27: 0 | AP27: 161100.65 | AQ27: 1 | AS27: 4583319.7 | AV27: 161100.65 | AW27: 5 | AY27: 527977.83
E28: 26 | F28: 1419119.8 | G28: 3941.9994 | I28: 44587 | J28: 37809.031 | K28: 38383.173 | L28: 0 | M28: 0 | N28: 43636.651 | O28: 41223.375 | P28: 0 | Q28: 0 | T28: 0 | AP28: 161052.23 | AQ28: 1 | AS28: 4744371.9 | AV28: 161052.23 | AW28: 5 | AY28: 689030.06
E29: 27 | F29: 1395607.6 | G29: 3876.6877 | I29: 44588 | J29: 37797.667 | K29: 38371.637 | L29: 0 | M29: 0 | N29: 43116.285 | O29: 41210.984 | P29: 0 | Q29: 0 | T29: 0 | AP29: 160496.57 | AQ29: 1 | AS29: 4904868.5 | AV29: 160496.57 | AW29: 5 | AY29: 849526.63
E30: 28 | F30: 1372187.9 | G30: 3811.6332 | I30: 44589 | J30: 37786.306 | K30: 38360.103 | L30: 0 | M30: 0 | N30: 43103.326 | O30: 41198.598 | P30: 0 | Q30: 0 | T30: 0 | AP30: 160448.33 | AQ30: 1 | AS30: 5065316.8 | AV30: 160448.33 | AW30: 5 | AY30: 1009975
E31: 29 | F31: 1348860.6 | G31: 3746.835 | I31: 44590 | J31: 37774.949 | K31: 38348.573 | L31: 0 | M31: 0 | N31: 43090.37 | O31: 41186.215 | P31: 0 | Q31: 0 | T31: 0 | AP31: 160400.11 | AQ31: 1 | AS31: 5225716.9 | AV31: 160400.11 | AW31: 5 | AX31: 5 | AY31: 1170375.1 | AZ31: 1170375.1
E32: 30 | F32: 1325625.3 | G32: 3682.2925 | I32: 44591 | J32: 37763.595 | K32: 38337.047 | L32: 0 | M32: 0 | N32: 43077.418 | O32: 43715.43 | P32: 0 | Q32: 0 | T32: 0 | AP32: 162893.49 | AQ32: 1 | AS32: 5388610.4 | AV32: 162893.49 | AW32: 6 | AY32: 162893.49
E33: 31 | F33: 1300127.4 | G33: 3611.465 | I33: 44592 | J33: 37752.244 | K33: 37827.79 | L33: 0 | M33: 0 | N33: 43064.47 | O33: 43702.29 | P33: 0 | Q33: 0 | T33: 0 | AP33: 162346.79 | AQ33: 1 | AR33: 1 | AS33: 5550957.2 | AT33: 5550957.2 | AV33: 162346.79 | AW33: 6 | AY33: 325240.28
E34: 32 | F34: 1160545.8 | G34: 3223.7382 | I34: 44593 | J34: 37244.306 | K34: 37816.42 | L34: 0 | M34: 0 | N34: 43051.526 | O34: 43689.155 | P34: 0 | Q34: 0 | T34: 0 | AP34: 161801.41 | AQ34: 2 | AS34: 161801.41 | AV34: 161801.41 | AW34: 6 | AY34: 487041.69
E35: 33 | F35: 959320.52 | G35: 2664.7792 | I35: 44594 | J35: 37233.111 | K35: 37805.053 | L35: 0 | M35: 0 | N35: 43038.586 | O35: 43676.023 | P35: 0 | Q35: 0 | T35: 0 | AP35: 161752.77 | AQ35: 2 | AS35: 323554.18 | AV35: 161752.77 | AW35: 6 | AY35: 648794.46
E36: 34 | F36: 920633.73 | G36: 2557.3159 | I36: 44595 | J36: 37221.92 | K36: 37793.69 | L36: 0 | M36: 0 | N36: 42519.466 | O36: 43662.895 | P36: 0 | Q36: 0 | T36: 0 | AP36: 161197.97 | AQ36: 2 | AS36: 484752.15 | AV36: 161197.97 | AW36: 6 | AY36: 809992.44
E37: 35 | F37: 905057.37 | G37: 2514.0482 | I37: 44596 | J37: 37210.732 | K37: 37782.33 | L37: 0 | M37: 0 | N37: 42506.686 | O37: 43649.771 | P37: 0 | Q37: 0 | T37: 0 | AP37: 161149.52 | AQ37: 2 | AS37: 645901.67 | AV37: 161149.52 | AW37: 6 | AY37: 971141.96
E38: 36 | F38: 889542.43 | G38: 2470.9512 | I38: 44597 | J38: 37199.548 | K38: 37770.974 | L38: 0 | M38: 0 | N38: 42493.91 | O38: 43636.651 | P38: 0 | Q38: 0 | T38: 0 | AP38: 161101.08 | AQ38: 2 | AS38: 807002.76 | AV38: 161101.08 | AW38: 6 | AX38: 6 | AY38: 1132243 | AZ38: 1132243
E39: 37 | F39: 874088.72 | G39: 2428.0242 | I39: 44598 | J39: 37188.367 | K39: 37759.621 | L39: 0 | M39: 0 | N39: 42481.137 | O39: 43116.285 | P39: 0 | Q39: 0 | T39: 0 | AP39: 160545.41 | AQ39: 2 | AS39: 967548.17 | AV39: 160545.41 | AW39: 7 | AY39: 160545.41
E40: 38 | F40: 858696.04 | G40: 2385.2668 | I40: 44599 | J40: 37177.189 | K40: 37251.584 | L40: 0 | M40: 0 | N40: 42468.369 | O40: 43103.326 | P40: 0 | Q40: 0 | T40: 0 | AP40: 160000.47 | AQ40: 2 | AS40: 1127548.6 | AV40: 160000.47 | AW40: 7 | AY40: 320545.88
...

Sheet Aprov
J1: AA | K1: BB | L1: CC | M1: DD | N1: EE | O1: FF | P1: GG | Q1: HH | R1: II | S1: JJ | T1: KK | U1: LL | V1: MM | W1: NN | X1: OO | Y1: PP | Z1: QQ | AA1: RR | AB1: SS | AC1: TT | AD1: UU | AE1: VV | AF1: XX | AG1: YY | AH1: ZZ | AI1: WW | AJ1: AAA | AK1: BBB | AL1: CCC | AM1: DDD | AN1: EEE | AX1: 53
B2: Mês | C2: Aproveitamento | F2: Caixas | G2: Caixas | J2: SJ F1 A 221 R | K2: SJ F1 B 321 R | L2: SJ F1 A 222 R | M2: SJ F1 B 322 R | N2: SJ F2 A 421 R | O2: SJ F2 B 521 R | P2: SJ F2 A 422 R | Q2: SJ F2 B 522 R | R2: SJ F3 820 R | S2: AAA 1 001 | T2: SJ F3 821 R | U2: AAA 1 001 | V2: AAA 1 001 | W2: AAA 1 001 | X2: AAA 1 001 | Y2: AAA 1 001 | Z2: AAA 1 001 | AA2: AAA 1 001 | AB2: AAA 1 001 | AC2: AAA 1 001 | AD2: AAA 1 001 | AE2: AAA 1 001 | AF2: AAA 1 001 | AG2: AAA 1 001 | AH2: AAA 1 001 | AI2: AAA 1 001 | AJ2: AAA 1 001 | AK2: AAA 1 001 | AL2: AAA 1 001 | AM2: AAA 1 001 | AN2: AAA 1 001
A3: 1 | B3: Jan | C3: 5397024.6 | E3: 1 | F3: 153636.62 | G3: 426.7684 | I3: 44562 | J3: 39928.763 | K3: 40508.772 | L3: 0 | M3: 0 | N3: 22758.701 | O3: 4743.7061 | P3: 0 | Q3: 0 | R3: 45696.68 | T3: 0 | AP3: 153636.62 | AQ3: 1 | AS3: 153636.62 | AV3: 153636.62 | AW3: 1 | AX3: 1 | AY3: 153636.62 | AZ3: 153636.62
A4: 2 | B4: Fev | C4: 4379396.8 | E4: 2 | F4: 1128840.7 | G4: 3135.6686 | I4: 44563 | J4: 39916.762 | K4: 40496.597 | L4: 0 | M4: 0 | N4: 22750.15 | O4: 9272.259 | P4: 0 | Q4: 0 | R4: 45682.945 | T4: 0 | AP4: 158118.71 | AQ4: 1 | AS4: 311755.34 | AV4: 158118.71 | AW4: 2 | AY4: 158118.71
A5: 3 | B5: Mar | C5: 4551861.3 | E5: 3 | F5: 1271975.3 | G5: 3533.2648 | I5: 44564 | J5: 39904.764 | K5: 39984.617 | L5: 0 | M5: 0 | N5: 22741.603 | O5: 9268.6359 | P5: 0 | Q5: 0 | R5: 44807.531 | T5: 0 | AP5: 156707.15 | AQ5: 1 | AS5: 468462.49 | AV5: 156707.15 | AW5: 2 | AY5: 314825.86
A6: 4 | B6: Abr | C6: 4106131.3 | E6: 4 | F6: 1363917.9 | G6: 3788.6608 | I6: 44565 | J6: 39394.11 | K6: 39972.599 | L6: 0 | M6: 0 | N6: 22733.058 | O6: 9265.0142 | P6: 0 | Q6: 0 | R6: 44794.063 | T6: 0 | AP6: 156158.84 | AQ6: 1 | AS6: 624621.33 | AV6: 156158.84 | AW6: 2 | AY6: 470984.71
A7: 5 | B7: Mai | C7: 4650834 | E7: 5 | F7: 1156135.8 | G7: 3211.4883 | I7: 44566 | J7: 39382.269 | K7: 39960.584 | L7: 0 | M7: 0 | N7: 22724.517 | O7: 9261.394 | P7: 0 | Q7: 0 | R7: 44780.599 | T7: 0 | AP7: 156109.36 | AQ7: 1 | AS7: 780730.69 | AV7: 156109.36 | AW7: 2 | AY7: 627094.07
A8: 6 | B8: Jun | C8: 5959727.2 | E8: 6 | F8: 1122753.2 | G8: 3118.7588 | I8: 44567 | J8: 39370.432 | K8: 39948.573 | L8: 0 | M8: 0 | N8: 33956.066 | O8: 9257.7752 | P8: 0 | Q8: 0 | R8: 44767.139 | T8: 0 | AP8: 167299.99 | AQ8: 1 | AS8: 948030.68 | AV8: 167299.99 | AW8: 2 | AY8: 794394.06
A9: 7 | B9: Jul | C9: 5858924.5 | E9: 7 | F9: 1107732.8 | G9: 3077.0357 | I9: 44568 | J9: 39358.598 | K9: 39936.566 | L9: 0 | M9: 0 | N9: 33945.86 | O9: 9254.1578 | P9: 0 | Q9: 0 | R9: 44753.684 | T9: 0 | AP9: 167248.87 | AQ9: 1 | AS9: 1115279.5 | AV9: 167248.87 | AW9: 2 | AY9: 961642.92
A10: 8 | B10: Ago | C10: 4223257.3 | E10: 8 | F10: 1090862.6 | G10: 3030.1738 | I10: 44569 | J10: 39346.768 | K10: 39924.562 | L10: 0 | M10: 0 | N10: 33935.656 | O10: 9250.5418 | P10: 0 | Q10: 0 | R10: 44740.232 | T10: 0 | AP10: 167197.76 | AQ10: 1 | AS10: 1282477.3 | AV10: 167197.76 | AW10: 2 | AX10: 2 | AY10: 1128840.7 | AZ10: 1128840.7
A11: 9 | B11: Set | C11: 3609095.1 | E11: 9 | F11: 1076028.9 | G11: 2988.9692 | I11: 44570 | J11: 39334.942 | K11: 39912.562 | L11: 0 | M11: 0 | N11: 33925.456 | O11: 22775.812 | P11: 0 | Q11: 0 | R11: 44726.784 | T11: 0 | AP11: 180675.56 | AQ11: 1 | AS11: 1463152.9 | AV11: 180675.56 | AW11: 3 | AY11: 180675.56
A12: 10 | B12: Out | C12: 2514925.3 | E12: 10 | F12: 1059923 | G12: 2944.2305 | I12: 44571 | J12: 39323.119 | K12: 39401.808 | L12: 0 | M12: 0 | N12: 33915.259 | O12: 22767.255 | P12: 0 | Q12: 0 | R12: 43853.469 | T12: 0 | AP12: 179260.91 | AQ12: 1 | AS12: 1642413.8 | AV12: 179260.91 | AW12: 3 | AY12: 359936.47
A13: 11 | B13: Nov | C13: 2258934.8 | E13: 11 | F13: 1043880 | G13: 2899.6666 | I13: 44572 | J13: 38813.688 | K13: 39389.965 | L13: 0 | M13: 0 | N13: 33905.065 | O13: 22758.701 | P13: 0 | Q13: 0 | R13: 43840.288 | T13: 0 | AP13: 178707.71 | AQ13: 1 | AS13: 1821121.5 | AV13: 178707.71 | AW13: 3 | AY13: 538644.17
A14: 12 | B14: Dez | C14: 4227304.6 | E14: 12 | F14: 1027899.7 | G14: 2855.277 | I14: 44573 | J14: 38802.022 | K14: 39378.125 | L14: 0 | M14: 0 | N14: 33894.875 | O14: 22750.15 | P14: 0 | Q14: 0 | R14: 43827.11 | T14: 0 | AP14: 178652.28 | AQ14: 1 | AS14: 1999773.8 | AV14: 178652.28 | AW14: 3 | AY14: 717296.46
B15: 2022 | C15: 51737417 | E15: 13 | F15: 1011982.1 | G15: 2811.0613 | I15: 44574 | J15: 38790.359 | K15: 39366.29 | L15: 0 | M15: 0 | N15: 40238.065 | O15: 22741.603 | P15: 0 | Q15: 0 | R15: 43813.937 | T15: 0 | AP15: 184950.25 | AQ15: 1 | AS15: 2184724 | AV15: 184950.25 | AW15: 3 | AY15: 902246.71
E16: 14 | F16: 996126.77 | G16: 2767.0188 | I16: 44575 | J16: 38778.7 | K16: 39354.457 | L16: 0 | M16: 0 | N16: 40225.971 | O16: 22733.058 | P16: 0 | Q16: 0 | R16: 43800.768 | T16: 0 | AP16: 184892.95 | AQ16: 1 | AS16: 2369617 | AV16: 184892.95 | AW16: 3 | AY16: 1087139.7
E17: 15 | F17: 980333.66 | G17: 2723.1491 | I17: 44576 | J17: 38767.044 | K17: 39342.628 | L17: 0 | M17: 0 | N17: 40213.88 | O17: 22724.517 | P17: 0 | Q17: 0 | R17: 43787.603 | T17: 0 | AP17: 184835.67 | AQ17: 1 | AS17: 2554452.6 | AV17: 184835.67 | AW17: 3 | AX17: 3 | AY17: 1271975.3 | AZ17: 1271975.3
E18: 16 | F18: 964037.96 | G18: 2677.8832 | I18: 44577 | J18: 38755.392 | K18: 39330.803 | L18: 0 | M18: 0 | N18: 40201.793 | O18: 33956.066 | P18: 0 | Q18: 0 | R18: 43774.442 | T18: 0 | AP18: 196018.5 | AQ18: 1 | AS18: 2750471.1 | AV18: 196018.5 | AW18: 4 | AY18: 196018.5
E19: 17 | F19: 947625.45 | G19: 2632.2929 | I19: 44578 | J19: 38743.743 | K19: 38821.273 | L19: 0 | M19: 0 | N19: 40189.71 | O19: 33945.86 | P19: 0 | Q19: 0 | R19: 42045.155 | T19: 0 | AP19: 193745.74 | AQ19: 1 | AS19: 2944216.9 | AV19: 193745.74 | AW19: 4 | AY19: 389764.24
E20: 18 | F20: 930721.65 | G20: 2585.3379 | I20: 44579 | J20: 38235.532 | K20: 38809.604 | L20: 0 | M20: 0 | N20: 40177.63 | O20: 33935.656 | P20: 0 | Q20: 0 | R20: 42032.518 | T20: 0 | AP20: 193190.94 | AQ20: 1 | AS20: 3137407.8 | AV20: 193190.94 | AW20: 4 | AY20: 582955.18
E21: 19 | F21: 915216.32 | G21: 2542.2675 | I21: 44580 | J21: 38224.04 | K21: 38797.939 | L21: 0 | M21: 0 | N21: 40165.553 | O21: 33925.456 | P21: 0 | Q21: 0 | R21: 42019.884 | T21: 0 | AP21: 193132.87 | AQ21: 1 | AS21: 3330540.7 | AV21: 193132.87 | AW21: 4 | AY21: 776088.05
E22: 20 | F22: 966276.88 | G22: 2684.1025 | I22: 44581 | J22: 38212.551 | K22: 38786.278 | L22: 0 | M22: 0 | N22: 43080.85 | O22: 33915.259 | P22: 0 | Q22: 0 | R22: 42007.254 | T22: 0 | AP22: 196002.19 | AQ22: 1 | AS22: 3526542.9 | AV22: 196002.19 | AW22: 4 | AY22: 972090.24
E23: 21 | F23: 1013307.8 | G23: 2814.7439 | I23: 44582 | J23: 38201.065 | K23: 38774.619 | L23: 0 | M23: 0 | N23: 43067.901 | O23: 33905.065 | P23: 0 | Q23: 0 | R23: 41994.628 | T23: 0 | AP23: 195943.28 | AQ23: 1 | AS23: 3722486.2 | AV23: 195943.28 | AW23: 4 | AY23: 1168033.5
E24: 22 | F24: 1185657.2 | G24: 3293.4921 | I24: 44583 | J24: 38189.583 | K24: 38762.965 | L24: 0 | M24: 0 | N24: 43054.956 | O24: 33894.875 | P24: 0 | Q24: 0 | R24: 41982.005 | T24: 0 | AP24: 195884.38 | AQ24: 1 | AS24: 3918370.5 | AV24: 195884.38 | AW24: 4 | AX24: 4 | AY24: 1363917.9 | AZ24: 1363917.9
E25: 23 | F25: 1326737.4 | G25: 3685.3816 | I25: 44584 | J25: 38178.104 | K25: 38751.314 | L25: 0 | M25: 0 | N25: 43042.015 | O25: 40238.065 | P25: 0 | Q25: 0 | R25: 41969.387 | T25: 0 | AP25: 202178.89 | AQ25: 1 | AS25: 4120549.4 | AV25: 202178.89 | AW25: 5 | AY25: 202178.89
E26: 24 | F26: 1398044.9 | G26: 3883.458 | I26: 44585 | J26: 38166.629 | K26: 38243.004 | L26: 0 | M26: 0 | N26: 43029.077 | O26: 40225.971 | P26: 0 | Q26: 0 | T26: 0 | AP26: 159664.68 | AQ26: 1 | AS26: 4280214.1 | AV26: 159664.68 | AW26: 5 | AY26: 361843.57
E27: 25 | F27: 1420495.9 | G27: 3945.8219 | I27: 44586 | J27: 37659.636 | K27: 38231.509 | L27: 0 | M27: 0 | N27: 43016.144 | O27: 40213.88 | P27: 0 | Q27: 0 | T27: 0 | AP27: 159121.17 | AQ27: 1 | AS27: 4439335.3 | AV27: 159121.17 | AW27: 5 | AY27: 520964.74
E28: 26 | F28: 1400081 | G28: 3889.1138 | I28: 44587 | J28: 37648.316 | K28: 38220.018 | L28: 0 | M28: 0 | N28: 43003.215 | O28: 40201.793 | P28: 0 | Q28: 0 | T28: 0 | AP28: 159073.34 | AQ28: 1 | AS28: 4598408.6 | AV28: 159073.34 | AW28: 5 | AY28: 680038.08
E29: 27 | F29: 1376903.9 | G29: 3824.7331 | I29: 44588 | J29: 37637 | K29: 38208.53 | L29: 0 | M29: 0 | N29: 42711.706 | O29: 40189.71 | P29: 0 | Q29: 0 | T29: 0 | AP29: 158746.95 | AQ29: 1 | AS29: 4757155.6 | AV29: 158746.95 | AW29: 5 | AY29: 838785.02
E30: 28 | F30: 1356828 | G30: 3768.9668 | I30: 44589 | J30: 37625.688 | K30: 38197.046 | L30: 0 | M30: 0 | N30: 42698.868 | O30: 40177.63 | P30: 0 | Q30: 0 | T30: 0 | AP30: 158699.23 | AQ30: 1 | AS30: 4915854.8 | AV30: 158699.23 | AW30: 5 | AY30: 997484.26
E31: 29 | F31: 1333790.7 | G31: 3704.9742 | I31: 44590 | J31: 37614.379 | K31: 38185.565 | L31: 0 | M31: 0 | N31: 42686.034 | O31: 40165.553 | P31: 0 | Q31: 0 | T31: 0 | AP31: 158651.53 | AQ31: 1 | AS31: 5074506.3 | AV31: 158651.53 | AW31: 5 | AX31: 5 | AY31: 1156135.8 | AZ31: 1156135.8
E32: 30 | F32: 1310399.7 | G32: 3639.9992 | I32: 44591 | J32: 37603.073 | K32: 38174.087 | L32: 0 | M32: 0 | N32: 42673.204 | O32: 43080.85 | P32: 0 | Q32: 0 | T32: 0 | AP32: 161531.21 | AQ32: 1 | AS32: 5236037.5 | AV32: 161531.21 | AW32: 6 | AY32: 161531.21
E33: 31 | F33: 1284664.2 | G33: 3568.5116 | I33: 44592 | J33: 37591.77 | K33: 37666.995 | L33: 0 | M33: 0 | N33: 42660.378 | O33: 43067.901 | P33: 0 | Q33: 0 | T33: 0 | AP33: 160987.04 | AQ33: 1 | AR33: 1 | AS33: 5397024.6 | AT33: 5397024.6 | AV33: 160987.04 | AW33: 6 | AY33: 322518.26
E34: 32 | F34: 1147239.7 | G34: 3186.777 | I34: 44593 | J34: 37085.991 | K34: 37655.673 | L34: 0 | M34: 0 | N34: 42647.555 | O34: 43054.956 | P34: 0 | Q34: 0 | T34: 0 | AP34: 160444.18 | AQ34: 2 | AS34: 160444.18 | AV34: 160444.18 | AW34: 6 | AY34: 482962.43
E35: 33 | F35: 949917.06 | G35: 2638.6585 | I35: 44594 | J35: 37074.844 | K35: 37644.355 | L35: 0 | M35: 0 | N35: 42634.737 | O35: 43042.015 | P35: 0 | Q35: 0 | T35: 0 | AP35: 160395.95 | AQ35: 2 | AS35: 320840.13 | AV35: 160395.95 | AW35: 6 | AY35: 643358.38
E36: 34 | F36: 910843.74 | G36: 2530.1215 | I36: 44595 | J36: 37063.701 | K36: 37633.04 | L36: 0 | M36: 0 | N36: 42120.488 | O36: 43029.077 | P36: 0 | Q36: 0 | T36: 0 | AP36: 159846.31 | AQ36: 2 | AS36: 480686.43 | AV36: 159846.31 | AW36: 6 | AY36: 803204.69
E37: 35 | F37: 893491.73 | G37: 2481.9215 | I37: 44596 | J37: 37052.561 | K37: 37621.729 | L37: 0 | M37: 0 | N37: 42107.827 | O37: 43016.144 | P37: 0 | Q37: 0 | T37: 0 | AP37: 159798.26 | AQ37: 2 | AS37: 640484.69 | AV37: 159798.26 | AW37: 6 | AY37: 963002.95
E38: 36 | F38: 878195.8 | G38: 2439.4328 | I38: 44597 | J38: 37041.424 | K38: 37610.421 | L38: 0 | M38: 0 | N38: 42095.171 | O38: 43003.215 | P38: 0 | Q38: 0 | T38: 0 | AP38: 159750.23 | AQ38: 2 | AS38: 800234.92 | AV38: 159750.23 | AW38: 6 | AX38: 6 | AY38: 1122753.2 | AZ38: 1122753.2
E39: 37 | F39: 860327.02 | G39: 2389.7973 | I39: 44598 | J39: 37030.29 | K39: 37599.116 | L39: 0 | M39: 0 | N39: 42082.518 | O39: 42711.706 | P39: 0 | Q39: 0 | T39: 0 | AP39: 159423.63 | AQ39: 2 | AS39: 959658.55 | AV39: 159423.63 | AW39: 7 | AY39: 159423.63
E40: 38 | F40: 845192.67 | G40: 2347.7574 | I40: 44599 | J40: 37019.16 | K40: 37093.238 | L40: 0 | M40: 0 | N40: 42069.869 | O40: 42698.868 | P40: 0 | Q40: 0 | T40: 0 | AP40: 158881.14 | AQ40: 2 | AS40: 1118539.7 | AV40: 158881.14 | AW40: 7 | AY40: 318304.77
...

Sheet Idade
J1: AA | K1: BB | L1: CC | M1: DD | N1: EE | O1: FF | P1: GG | Q1: HH | R1: II | S1: JJ | T1: KK | U1: LL | V1: MM | W1: NN | X1: OO | Y1: PP | Z1: QQ | AA1: RR | AB1: SS | AC1: TT | AD1: UU | AE1: VV | AF1: XX | AG1: YY | AH1: ZZ | AI1: WW | AJ1: AAA | AK1: BBB | AL1: CCC | AM1: DDD | AN1: EEE | AX1: 53
B2: Mês | C2: Ovos Totais | F2: Ovos Totais | G2: Caixas | J2: SJ F1 A 221 R | K2: SJ F1 B 321 R | L2: SJ F1 A 222 R | M2: SJ F1 B 322 R | N2: SJ F2 A 421 R | O2: SJ F2 B 521 R | P2: SJ F2 A 422 R | Q2: SJ F2 B 522 R | R2: SJ F3 820 R | S2: AAA 1 001 | T2: SJ F3 821 R | U2: AAA 1 001 | V2: AAA 1 001 | W2: AAA 1 001 | X2: AAA 1 001 | Y2: AAA 1 001 | Z2: AAA 1 001 | AA2: AAA 1 001 | AB2: AAA 1 001 | AC2: AAA 1 001 | AD2: AAA 1 001 | AE2: AAA 1 001 | AF2: AAA 1 001 | AG2: AAA 1 001 | AH2: AAA 1 001 | AI2: AAA 1 001 | AJ2: AAA 1 001 | AK2: AAA 1 001 | AL2: AAA 1 001 | AM2: AAA 1 001 | AN2: AAA 1 001 | AP2: Total
A3: 1 | B3: Jan | C3: 5591 | E3: 1 | F3: 186 | G3: 0.51666667 | I3: 44562 | J3: 36 | K3: 35 | L3: 0 | M3: 0 | N3: 27 | O3: 25 | P3: 0 | Q3: 0 | R3: 63 | S3: 0 | T3: 0 | U3: 0 | V3: 0 | W3: 0 | X3: 0 | Y3: 0 | Z3: 0 | AA3: 0 | AB3: 0 | AC3: 0 | AD3: 0 | AE3: 0 | AF3: 0 | AG3: 0 | AH3: 0 | AI3: 0 | AJ3: 0 | AK3: 0 | AL3: 0 | AM3: 0 | AN3: 0 | AP3: 186 | AQ3: 1 | AS3: 186 | AV3: 186 | AW3: 1 | AX3: 1 | AY3: 186 | AZ3: 186
A4: 2 | B4: Fev | C4: 4176 | E4: 2 | F4: 1329 | G4: 3.6916667 | I4: 44563 | J4: 36 | K4: 35 | L4: 0 | M4: 0 | N4: 27 | O4: 26 | P4: 0 | Q4: 0 | R4: 63 | S4: 0 | T4: 0 | U4: 0 | V4: 0 | W4: 0 | X4: 0 | Y4: 0 | Z4: 0 | AA4: 0 | AB4: 0 | AC4: 0 | AD4: 0 | AE4: 0 | AF4: 0 | AG4: 0 | AH4: 0 | AI4: 0 | AJ4: 0 | AK4: 0 | AL4: 0 | AM4: 0 | AN4: 0 | AP4: 187 | AQ4: 1 | AS4: 373 | AV4: 187 | AW4: 2 | AY4: 187
A5: 3 | B5: Mar | C5: 5147 | E5: 3 | F5: 1364 | G5: 3.7888889 | I5: 44564 | J5: 36 | K5: 36 | L5: 0 | M5: 0 | N5: 27 | O5: 26 | P5: 0 | Q5: 0 | R5: 64 | S5: 0 | T5: 0 | U5: 0 | V5: 0 | W5: 0 | X5: 0 | Y5: 0 | Z5: 0 | AA5: 0 | AB5: 0 | AC5: 0 | AD5: 0 | AE5: 0 | AF5: 0 | AG5: 0 | AH5: 0 | AI5: 0 | AJ5: 0 | AK5: 0 | AL5: 0 | AM5: 0 | AN5: 0 | AP5: 189 | AQ5: 1 | AS5: 562 | AV5: 189 | AW5: 2 | AY5: 376
A6: 4 | B6: Abr | C6: 5817 | E6: 4 | F6: 1399 | G6: 3.8861111 | I6: 44565 | J6: 37 | K6: 36 | L6: 0 | M6: 0 | N6: 27 | O6: 26 | P6: 0 | Q6: 0 | R6: 64 | S6: 0 | T6: 0 | U6: 0 | V6: 0 | W6: 0 | X6: 0 | Y6: 0 | Z6: 0 | AA6: 0 | AB6: 0 | AC6: 0 | AD6: 0 | AE6: 0 | AF6: 0 | AG6: 0 | AH6: 0 | AI6: 0 | AJ6: 0 | AK6: 0 | AL6: 0 | AM6: 0 | AN6: 0 | AP6: 190 | AQ6: 1 | AS6: 752 | AV6: 190 | AW6: 2 | AY6: 566
A7: 5 | B7: Mai | C7: 7025 | E7: 5 | F7: 1032 | G7: 2.8666667 | I7: 44566 | J7: 37 | K7: 36 | L7: 0 | M7: 0 | N7: 27 | O7: 26 | P7: 0 | Q7: 0 | R7: 64 | S7: 0 | T7: 0 | U7: 0 | V7: 0 | W7: 0 | X7: 0 | Y7: 0 | Z7: 0 | AA7: 0 | AB7: 0 | AC7: 0 | AD7: 0 | AE7: 0 | AF7: 0 | AG7: 0 | AH7: 0 | AI7: 0 | AJ7: 0 | AK7: 0 | AL7: 0 | AM7: 0 | AN7: 0 | AP7: 190 | AQ7: 1 | AS7: 942 | AV7: 190 | AW7: 2 | AY7: 756
A8: 6 | B8: Jun | C8: 7451 | E8: 6 | F8: 994 | G8: 2.7611111 | I8: 44567 | J8: 37 | K8: 36 | L8: 0 | M8: 0 | N8: 28 | O8: 26 | P8: 0 | Q8: 0 | R8: 64 | S8: 0 | T8: 0 | U8: 0 | V8: 0 | W8: 0 | X8: 0 | Y8: 0 | Z8: 0 | AA8: 0 | AB8: 0 | AC8: 0 | AD8: 0 | AE8: 0 | AF8: 0 | AG8: 0 | AH8: 0 | AI8: 0 | AJ8: 0 | AK8: 0 | AL8: 0 | AM8: 0 | AN8: 0 | AP8: 191 | AQ8: 1 | AS8: 1133 | AV8: 191 | AW8: 2 | AY8: 947
A9: 7 | B9: Jul | C9: 8373 | E9: 7 | F9: 1022 | G9: 2.8388889 | I9: 44568 | J9: 37 | K9: 36 | L9: 0 | M9: 0 | N9: 28 | O9: 26 | P9: 0 | Q9: 0 | R9: 64 | S9: 0 | T9: 0 | U9: 0 | V9: 0 | W9: 0 | X9: 0 | Y9: 0 | Z9: 0 | AA9: 0 | AB9: 0 | AC9: 0 | AD9: 0 | AE9: 0 | AF9: 0 | AG9: 0 | AH9: 0 | AI9: 0 | AJ9: 0 | AK9: 0 | AL9: 0 | AM9: 0 | AN9: 0 | AP9: 191 | AQ9: 1 | AS9: 1324 | AV9: 191 | AW9: 2 | AY9: 1138
A10: 8 | B10: Ago | C10: 5364 | E10: 8 | F10: 1050 | G10: 2.9166667 | I10: 44569 | J10: 37 | K10: 36 | L10: 0 | M10: 0 | N10: 28 | O10: 26 | P10: 0 | Q10: 0 | R10: 64 | S10: 0 | T10: 0 | U10: 0 | V10: 0 | W10: 0 | X10: 0 | Y10: 0 | Z10: 0 | AA10: 0 | AB10: 0 | AC10: 0 | AD10: 0 | AE10: 0 | AF10: 0 | AG10: 0 | AH10: 0 | AI10: 0 | AJ10: 0 | AK10: 0 | AL10: 0 | AM10: 0 | AN10: 0 | AP10: 191 | AQ10: 1 | AS10: 1515 | AV10: 191 | AW10: 2 | AX10: 2 | AY10: 1329 | AZ10: 1329
A11: 9 | B11: Set | C11: 5072 | E11: 9 | F11: 1078 | G11: 2.9944444 | I11: 44570 | J11: 37 | K11: 36 | L11: 0 | M11: 0 | N11: 28 | O11: 27 | P11: 0 | Q11: 0 | R11: 64 | S11: 0 | T11: 0 | U11: 0 | V11: 0 | W11: 0 | X11: 0 | Y11: 0 | Z11: 0 | AA11: 0 | AB11: 0 | AC11: 0 | AD11: 0 | AE11: 0 | AF11: 0 | AG11: 0 | AH11: 0 | AI11: 0 | AJ11: 0 | AK11: 0 | AL11: 0 | AM11: 0 | AN11: 0 | AP11: 192 | AQ11: 1 | AS11: 1707 | AV11: 192 | AW11: 3 | AY11: 192
A12: 10 | B12: Out | C12: 3210 | E12: 10 | F12: 1106 | G12: 3.0722222 | I12: 44571 | J12: 37 | K12: 37 | L12: 0 | M12: 0 | N12: 28 | O12: 27 | P12: 0 | Q12: 0 | R12: 65 | S12: 0 | T12: 0 | U12: 0 | V12: 0 | W12: 0 | X12: 0 | Y12: 0 | Z12: 0 | AA12: 0 | AB12: 0 | AC12: 0 | AD12: 0 | AE12: 0 | AF12: 0 | AG12: 0 | AH12: 0 | AI12: 0 | AJ12: 0 | AK12: 0 | AL12: 0 | AM12: 0 | AN12: 0 | AP12: 194 | AQ12: 1 | AS12: 1901 | AV12: 194 | AW12: 3 | AY12: 386
A13: 11 | B13: Nov | C13: 3080 | E13: 11 | F13: 1134 | G13: 3.15 | I13: 44572 | J13: 38 | K13: 37 | L13: 0 | M13: 0 | N13: 28 | O13: 27 | P13: 0 | Q13: 0 | R13: 65 | S13: 0 | T13: 0 | U13: 0 | V13: 0 | W13: 0 | X13: 0 | Y13: 0 | Z13: 0 | AA13: 0 | AB13: 0 | AC13: 0 | AD13: 0 | AE13: 0 | AF13: 0 | AG13: 0 | AH13: 0 | AI13: 0 | AJ13: 0 | AK13: 0 | AL13: 0 | AM13: 0 | AN13: 0 | AP13: 195 | AQ13: 1 | AS13: 2096 | AV13: 195 | AW13: 3 | AY13: 581
A14: 12 | B14: Dez | C14: 4888 | E14: 12 | F14: 1162 | G14: 3.2277778 | I14: 44573 | J14: 38 | K14: 37 | L14: 0 | M14: 0 | N14: 28 | O14: 27 | P14: 0 | Q14: 0 | R14: 65 | S14: 0 | T14: 0 | U14: 0 | V14: 0 | W14: 0 | X14: 0 | Y14: 0 | Z14: 0 | AA14: 0 | AB14: 0 | AC14: 0 | AD14: 0 | AE14: 0 | AF14: 0 | AG14: 0 | AH14: 0 | AI14: 0 | AJ14: 0 | AK14: 0 | AL14: 0 | AM14: 0 | AN14: 0 | AP14: 195 | AQ14: 1 | AS14: 2291 | AV14: 195 | AW14: 3 | AY14: 776
B15: 2022 | C15: 65194 | E15: 13 | F15: 1190 | G15: 3.3055556 | I15: 44574 | J15: 38 | K15: 37 | L15: 0 | M15: 0 | N15: 29 | O15: 27 | P15: 0 | Q15: 0 | R15: 65 | S15: 0 | T15: 0 | U15: 0 | V15: 0 | W15: 0 | X15: 0 | Y15: 0 | Z15: 0 | AA15: 0 | AB15: 0 | AC15: 0 | AD15: 0 | AE15: 0 | AF15: 0 | AG15: 0 | AH15: 0 | AI15: 0 | AJ15: 0 | AK15: 0 | AL15: 0 | AM15: 0 | AN15: 0 | AP15: 196 | AQ15: 1 | AS15: 2487 | AV15: 196 | AW15: 3 | AY15: 972
E16: 14 | F16: 1218 | G16: 3.3833333 | I16: 44575 | J16: 38 | K16: 37 | L16: 0 | M16: 0 | N16: 29 | O16: 27 | P16: 0 | Q16: 0 | R16: 65 | S16: 0 | T16: 0 | U16: 0 | V16: 0 | W16: 0 | X16: 0 | Y16: 0 | Z16: 0 | AA16: 0 | AB16: 0 | AC16: 0 | AD16: 0 | AE16: 0 | AF16: 0 | AG16: 0 | AH16: 0 | AI16: 0 | AJ16: 0 | AK16: 0 | AL16: 0 | AM16: 0 | AN16: 0 | AP16: 196 | AQ16: 1 | AS16: 2683 | AV16: 196 | AW16: 3 | AY16: 1168
E17: 15 | F17: 1246 | G17: 3.4611111 | I17: 44576 | J17: 38 | K17: 37 | L17: 0 | M17: 0 | N17: 29 | O17: 27 | P17: 0 | Q17: 0 | R17: 65 | S17: 0 | T17: 0 | U17: 0 | V17: 0 | W17: 0 | X17: 0 | Y17: 0 | Z17: 0 | AA17: 0 | AB17: 0 | AC17: 0 | AD17: 0 | AE17: 0 | AF17: 0 | AG17: 0 | AH17: 0 | AI17: 0 | AJ17: 0 | AK17: 0 | AL17: 0 | AM17: 0 | AN17: 0 | AP17: 196 | AQ17: 1 | AS17: 2879 | AV17: 196 | AW17: 3 | AX17: 3 | AY17: 1364 | AZ17: 1364
E18: 16 | F18: 1274 | G18: 3.5388889 | I18: 44577 | J18: 38 | K18: 37 | L18: 0 | M18: 0 | N18: 29 | O18: 28 | P18: 0 | Q18: 0 | R18: 65 | S18: 0 | T18: 0 | U18: 0 | V18: 0 | W18: 0 | X18: 0 | Y18: 0 | Z18: 0 | AA18: 0 | AB18: 0 | AC18: 0 | AD18: 0 | AE18: 0 | AF18: 0 | AG18: 0 | AH18: 0 | AI18: 0 | AJ18: 0 | AK18: 0 | AL18: 0 | AM18: 0 | AN18: 0 | AP18: 197 | AQ18: 1 | AS18: 3076 | AV18: 197 | AW18: 4 | AY18: 197
E19: 17 | F19: 1456 | G19: 4.0444444 | I19: 44578 | J19: 38 | K19: 38 | L19: 0 | M19: 0 | N19: 29 | O19: 28 | P19: 0 | Q19: 0 | R19: 66 | S19: 0 | T19: 0 | U19: 0 | V19: 0 | W19: 0 | X19: 0 | Y19: 0 | Z19: 0 | AA19: 0 | AB19: 0 | AC19: 0 | AD19: 0 | AE19: 0 | AF19: 0 | AG19: 0 | AH19: 0 | AI19: 0 | AJ19: 0 | AK19: 0 | AL19: 0 | AM19: 0 | AN19: 0 | AP19: 199 | AQ19: 1 | AS19: 3275 | AV19: 199 | AW19: 4 | AY19: 396
E20: 18 | F20: 1491 | G20: 4.1416667 | I20: 44579 | J20: 39 | K20: 38 | L20: 0 | M20: 0 | N20: 29 | O20: 28 | P20: 0 | Q20: 0 | R20: 66 | S20: 0 | T20: 0 | U20: 0 | V20: 0 | W20: 0 | X20: 0 | Y20: 0 | Z20: 0 | AA20: 0 | AB20: 0 | AC20: 0 | AD20: 0 | AE20: 0 | AF20: 0 | AG20: 0 | AH20: 0 | AI20: 0 | AJ20: 0 | AK20: 0 | AL20: 0 | AM20: 0 | AN20: 0 | AP20: 200 | AQ20: 1 | AS20: 3475 | AV20: 200 | AW20: 4 | AY20: 596
E21: 19 | F21: 1526 | G21: 4.2388889 | I21: 44580 | J21: 39 | K21: 38 | L21: 0 | M21: 0 | N21: 29 | O21: 28 | P21: 0 | Q21: 0 | R21: 66 | S21: 0 | T21: 0 | U21: 0 | V21: 0 | W21: 0 | X21: 0 | Y21: 0 | Z21: 0 | AA21: 0 | AB21: 0 | AC21: 0 | AD21: 0 | AE21: 0 | AF21: 0 | AG21: 0 | AH21: 0 | AI21: 0 | AJ21: 0 | AK21: 0 | AL21: 0 | AM21: 0 | AN21: 0 | AP21: 200 | AQ21: 1 | AS21: 3675 | AV21: 200 | AW21: 4 | AY21: 796
E22: 20 | F22: 1561 | G22: 4.3361111 | I22: 44581 | J22: 39 | K22: 38 | L22: 0 | M22: 0 | N22: 30 | O22: 28 | P22: 0 | Q22: 0 | R22: 66 | S22: 0 | T22: 0 | U22: 0 | V22: 0 | W22: 0 | X22: 0 | Y22: 0 | Z22: 0 | AA22: 0 | AB22: 0 | AC22: 0 | AD22: 0 | AE22: 0 | AF22: 0 | AG22: 0 | AH22: 0 | AI22: 0 | AJ22: 0 | AK22: 0 | AL22: 0 | AM22: 0 | AN22: 0 | AP22: 201 | AQ22: 1 | AS22: 3876 | AV22: 201 | AW22: 4 | AY22: 997
E23: 21 | F23: 1596 | G23: 4.4333333 | I23: 44582 | J23: 39 | K23: 38 | L23: 0 | M23: 0 | N23: 30 | O23: 28 | P23: 0 | Q23: 0 | R23: 66 | S23: 0 | T23: 0 | U23: 0 | V23: 0 | W23: 0 | X23: 0 | Y23: 0 | Z23: 0 | AA23: 0 | AB23: 0 | AC23: 0 | AD23: 0 | AE23: 0 | AF23: 0 | AG23: 0 | AH23: 0 | AI23: 0 | AJ23: 0 | AK23: 0 | AL23: 0 | AM23: 0 | AN23: 0 | AP23: 201 | AQ23: 1 | AS23: 4077 | AV23: 201 | AW23: 4 | AY23: 1198
E24: 22 | F24: 1631 | G24: 4.5305556 | I24: 44583 | J24: 39 | K24: 38 | L24: 0 | M24: 0 | N24: 30 | O24: 28 | P24: 0 | Q24: 0 | R24: 66 | S24: 0 | T24: 0 | U24: 0 | V24: 0 | W24: 0 | X24: 0 | Y24: 0 | Z24: 0 | AA24: 0 | AB24: 0 | AC24: 0 | AD24: 0 | AE24: 0 | AF24: 0 | AG24: 0 | AH24: 0 | AI24: 0 | AJ24: 0 | AK24: 0 | AL24: 0 | AM24: 0 | AN24: 0 | AP24: 201 | AQ24: 1 | AS24: 4278 | AV24: 201 | AW24: 4 | AX24: 4 | AY24: 1399 | AZ24: 1399
E25: 23 | F25: 1666 | G25: 4.6277778 | I25: 44584 | J25: 39 | K25: 38 | L25: 0 | M25: 0 | N25: 30 | O25: 29 | P25: 0 | Q25: 0 | R25: 66 | S25: 0 | T25: 0 | U25: 0 | V25: 0 | W25: 0 | X25: 0 | Y25: 0 | Z25: 0 | AA25: 0 | AB25: 0 | AC25: 0 | AD25: 0 | AE25: 0 | AF25: 0 | AG25: 0 | AH25: 0 | AI25: 0 | AJ25: 0 | AK25: 0 | AL25: 0 | AM25: 0 | AN25: 0 | AP25: 202 | AQ25: 1 | AS25: 4480 | AV25: 202 | AW25: 5 | AY25: 202
E26: 24 | F26: 1701 | G26: 4.725 | I26: 44585 | J26: 39 | K26: 39 | L26: 0 | M26: 0 | N26: 30 | O26: 29 | P26: 0 | Q26: 0 | R26: 0 | S26: 0 | T26: 0 | U26: 0 | V26: 0 | W26: 0 | X26: 0 | Y26: 0 | Z26: 0 | AA26: 0 | AB26: 0 | AC26: 0 | AD26: 0 | AE26: 0 | AF26: 0 | AG26: 0 | AH26: 0 | AI26: 0 | AJ26: 0 | AK26: 0 | AL26: 0 | AM26: 0 | AN26: 0 | AP26: 137 | AQ26: 1 | AS26: 4617 | AV26: 137 | AW26: 5 | AY26: 339
E27: 25 | F27: 1736 | G27: 4.8222222 | I27: 44586 | J27: 40 | K27: 39 | L27: 0 | M27: 0 | N27: 30 | O27: 29 | P27: 0 | Q27: 0 | R27: 0 | S27: 0 | T27: 0 | U27: 0 | V27: 0 | W27: 0 | X27: 0 | Y27: 0 | Z27: 0 | AA27: 0 | AB27: 0 | AC27: 0 | AD27: 0 | AE27: 0 | AF27: 0 | AG27: 0 | AH27: 0 | AI27: 0 | AJ27: 0 | AK27: 0 | AL27: 0 | AM27: 0 | AN27: 0 | AP27: 138 | AQ27: 1 | AS27: 4755 | AV27: 138 | AW27: 5 | AY27: 477
E28: 26 | F28: 1771 | G28: 4.9194444 | I28: 44587 | J28: 40 | K28: 39 | L28: 0 | M28: 0 | N28: 30 | O28: 29 | P28: 0 | Q28: 0 | R28: 0 | S28: 0 | T28: 0 | U28: 0 | V28: 0 | W28: 0 | X28: 0 | Y28: 0 | Z28: 0 | AA28: 0 | AB28: 0 | AC28: 0 | AD28: 0 | AE28: 0 | AF28: 0 | AG28: 0 | AH28: 0 | AI28: 0 | AJ28: 0 | AK28: 0 | AL28: 0 | AM28: 0 | AN28: 0 | AP28: 138 | AQ28: 1 | AS28: 4893 | AV28: 138 | AW28: 5 | AY28: 615
E29: 27 | F29: 1806 | G29: 5.0166667 | I29: 44588 | J29: 40 | K29: 39 | L29: 0 | M29: 0 | N29: 31 | O29: 29 | P29: 0 | Q29: 0 | R29: 0 | S29: 0 | T29: 0 | U29: 0 | V29: 0 | W29: 0 | X29: 0 | Y29: 0 | Z29: 0 | AA29: 0 | AB29: 0 | AC29: 0 | AD29: 0 | AE29: 0 | AF29: 0 | AG29: 0 | AH29: 0 | AI29: 0 | AJ29: 0 | AK29: 0 | AL29: 0 | AM29: 0 | AN29: 0 | AP29: 139 | AQ29: 1 | AS29: 5032 | AV29: 139 | AW29: 5 | AY29: 754
E30: 28 | F30: 1841 | G30: 5.1138889 | I30: 44589 | J30: 40 | K30: 39 | L30: 0 | M30: 0 | N30: 31 | O30: 29 | P30: 0 | Q30: 0 | R30: 0 | S30: 0 | T30: 0 | U30: 0 | V30: 0 | W30: 0 | X30: 0 | Y30: 0 | Z30: 0 | AA30: 0 | AB30: 0 | AC30: 0 | AD30: 0 | AE30: 0 | AF30: 0 | AG30: 0 | AH30: 0 | AI30: 0 | AJ30: 0 | AK30: 0 | AL30: 0 | AM30: 0 | AN30: 0 | AP30: 139 | AQ30: 1 | AS30: 5171 | AV30: 139 | AW30: 5 | AY30: 893
E31: 29 | F31: 1876 | G31: 5.2111111 | I31: 44590 | J31: 40 | K31: 39 | L31: 0 | M31: 0 | N31: 31 | O31: 29 | P31: 0 | Q31: 0 | R31: 0 | S31: 0 | T31: 0 | U31: 0 | V31: 0 | W31: 0 | X31: 0 | Y31: 0 | Z31: 0 | AA31: 0 | AB31: 0 | AC31: 0 | AD31: 0 | AE31: 0 | AF31: 0 | AG31: 0 | AH31: 0 | AI31: 0 | AJ31: 0 | AK31: 0 | AL31: 0 | AM31: 0 | AN31: 0 | AP31: 139 | AQ31: 1 | AS31: 5310 | AV31: 139 | AW31: 5 | AX31: 5 | AY31: 1032 | AZ31: 1032
E32: 30 | F32: 1911 | G32: 5.3083333 | I32: 44591 | J32: 40 | K32: 39 | L32: 0 | M32: 0 | N32: 31 | O32: 30 | P32: 0 | Q32: 0 | R32: 0 | S32: 0 | T32: 0 | U32: 0 | V32: 0 | W32: 0 | X32: 0 | Y32: 0 | Z32: 0 | AA32: 0 | AB32: 0 | AC32: 0 | AD32: 0 | AE32: 0 | AF32: 0 | AG32: 0 | AH32: 0 | AI32: 0 | AJ32: 0 | AK32: 0 | AL32: 0 | AM32: 0 | AN32: 0 | AP32: 140 | AQ32: 1 | AS32: 5450 | AV32: 140 | AW32: 6 | AY32: 140
E33: 31 | F33: 1946 | G33: 5.4055556 | I33: 44592 | J33: 40 | K33: 40 | L33: 0 | M33: 0 | N33: 31 | O33: 30 | P33: 0 | Q33: 0 | R33: 0 | S33: 0 | T33: 0 | U33: 0 | V33: 0 | W33: 0 | X33: 0 | Y33: 0 | Z33: 0 | AA33: 0 | AB33: 0 | AC33: 0 | AD33: 0 | AE33: 0 | AF33: 0 | AG33: 0 | AH33: 0 | AI33: 0 | AJ33: 0 | AK33: 0 | AL33: 0 | AM33: 0 | AN33: 0 | AP33: 141 | AQ33: 1 | AR33: 1 | AS33: 5591 | AT33: 5591 | AV33: 141 | AW33: 6 | AY33: 281
E34: 32 | F34: 1646 | G34: 4.5722222 | I34: 44593 | J34: 41 | K34: 40 | L34: 0 | M34: 0 | N34: 31 | O34: 30 | P34: 0 | Q34: 0 | R34: 0 | S34: 0 | T34: 0 | U34: 0 | V34: 0 | W34: 0 | X34: 0 | Y34: 0 | Z34: 0 | AA34: 0 | AB34: 0 | AC34: 0 | AD34: 0 | AE34: 0 | AF34: 0 | AG34: 0 | AH34: 0 | AI34: 0 | AJ34: 0 | AK34: 0 | AL34: 0 | AM34: 0 | AN34: 0 | AP34: 142 | AQ34: 2 | AS34: 142 | AV34: 142 | AW34: 6 | AY34: 423
E35: 33 | F35: 1140 | G35: 3.1666667 | I35: 44594 | J35: 41 | K35: 40 | L35: 0 | M35: 0 | N35: 31 | O35: 30 | P35: 0 | Q35: 0 | R35: 0 | S35: 0 | T35: 0 | U35: 0 | V35: 0 | W35: 0 | X35: 0 | Y35: 0 | Z35: 0 | AA35: 0 | AB35: 0 | AC35: 0 | AD35: 0 | AE35: 0 | AF35: 0 | AG35: 0 | AH35: 0 | AI35: 0 | AJ35: 0 | AK35: 0 | AL35: 0 | AM35: 0 | AN35: 0 | AP35: 142 | AQ35: 2 | AS35: 284 | AV35: 142 | AW35: 6 | AY35: 565
E36: 34 | F36: 1095 | G36: 3.0416667 | I36: 44595 | J36: 41 | K36: 40 | L36: 0 | M36: 0 | N36: 32 | O36: 30 | P36: 0 | Q36: 0 | R36: 0 | S36: 0 | T36: 0 | U36: 0 | V36: 0 | W36: 0 | X36: 0 | Y36: 0 | Z36: 0 | AA36: 0 | AB36: 0 | AC36: 0 | AD36: 0 | AE36: 0 | AF36: 0 | AG36: 0 | AH36: 0 | AI36: 0 | AJ36: 0 | AK36: 0 | AL36: 0 | AM36: 0 | AN36: 0 | AP36: 143 | AQ36: 2 | AS36: 427 | AV36: 143 | AW36: 6 | AY36: 708
E37: 35 | F37: 1116 | G37: 3.1 | I37: 44596 | J37: 41 | K37: 40 | L37: 0 | M37: 0 | N37: 32 | O37: 30 | P37: 0 | Q37: 0 | R37: 0 | S37: 0 | T37: 0 | U37: 0 | V37: 0 | W37: 0 | X37: 0 | Y37: 0 | Z37: 0 | AA37: 0 | AB37: 0 | AC37: 0 | AD37: 0 | AE37: 0 | AF37: 0 | AG37: 0 | AH37: 0 | AI37: 0 | AJ37: 0 | AK37: 0 | AL37: 0 | AM37: 0 | AN37: 0 | AP37: 143 | AQ37: 2 | AS37: 570 | AV37: 143 | AW37: 6 | AY37: 851
E38: 36 | F38: 1137 | G38: 3.1583333 | I38: 44597 | J38: 41 | K38: 40 | L38: 0 | M38: 0 | N38: 32 | O38: 30 | P38: 0 | Q38: 0 | R38: 0 | S38: 0 | T38: 0 | U38: 0 | V38: 0 | W38: 0 | X38: 0 | Y38: 0 | Z38: 0 | AA38: 0 | AB38: 0 | AC38: 0 | AD38: 0 | AE38: 0 | AF38: 0 | AG38: 0 | AH38: 0 | AI38: 0 | AJ38: 0 | AK38: 0 | AL38: 0 | AM38: 0 | AN38: 0 | AP38: 143 | AQ38: 2 | AS38: 713 | AV38: 143 | AW38: 6 | AX38: 6 | AY38: 994 | AZ38: 994
E39: 37 | F39: 1158 | G39: 3.2166667 | I39: 44598 | J39: 41 | K39: 40 | L39: 0 | M39: 0 | N39: 32 | O39: 31 | P39: 0 | Q39: 0 | R39: 0 | S39: 0 | T39: 0 | U39: 0 | V39: 0 | W39: 0 | X39: 0 | Y39: 0 | Z39: 0 | AA39: 0 | AB39: 0 | AC39: 0 | AD39: 0 | AE39: 0 | AF39: 0 | AG39: 0 | AH39: 0 | AI39: 0 | AJ39: 0 | AK39: 0 | AL39: 0 | AM39: 0 | AN39: 0 | AP39: 144 | AQ39: 2 | AS39: 857 | AV39: 144 | AW39: 7 | AY39: 144
E40: 38 | F40: 1179 | G40: 3.275 | I40: 44599 | J40: 41 | K40: 41 | L40: 0 | M40: 0 | N40: 32 | O40: 31 | P40: 0 | Q40: 0 | R40: 0 | S40: 0 | T40: 0 | U40: 0 | V40: 0 | W40: 0 | X40: 0 | Y40: 0 | Z40: 0 | AA40: 0 | AB40: 0 | AC40: 0 | AD40: 0 | AE40: 0 | AF40: 0 | AG40: 0 | AH40: 0 | AI40: 0 | AJ40: 0 | AK40: 0 | AL40: 0 | AM40: 0 | AN40: 0 | AP40: 145 | AQ40: 2 | AS40: 1002 | AV40: 145 | AW40: 7 | AY40: 289
...

Sheet Produção
D1: =OvoTotal!J1 -> AA | E1: =OvoTotal!K1 -> BB | F1: =OvoTotal!L1 -> CC | G1: =OvoTotal!M1 -> DD | H1: =OvoTotal!N1 -> EE | I1: =OvoTotal!O1 -> FF | J1: =OvoTotal!P1 -> GG | K1: =OvoTotal!Q1 -> HH | ... AH1: =OvoTotal!AN1 -> EEE
C2: Valor Ovo | D2: =OvoTotal!J2 -> SJ F1 A 221 R | E2: =OvoTotal!K2 -> SJ F1 B 321 R | F2: =OvoTotal!L2 -> SJ F1 A 222 R | G2: =OvoTotal!M2 -> SJ F1 B 322 R | H2: =OvoTotal!N2 -> SJ F2 A 421 R | I2: =OvoTotal!O2 -> SJ F2 B 521 R | J2: =OvoTotal!P2 -> SJ F2 A 422 R | K2: =OvoTotal!Q2 -> SJ F2 B 522 R | ... AH2: =OvoTotal!AN2 -> AAA 1 001
A3: =A60-1+(WEEKNUM(A60,2)+WEEKNUM(A60+1,2)+WEEKNUM(A60+2,2)+WEEKNUM(A60+3,2)+WEEKNUM(A60+4,2)+WEEKNUM(A60+5,2)+WEEKNUM(A60+6,2))-(((WEEKNUM(A60,2)+WEEKNUM(A60+1,2)+WEEKNUM(A60+2,2)+WEEKNUM(A60+3,2)+WEEKNUM(A60+4,2)+WEEKNUM(A60+5,2)+WEEKNUM(A60+6,2))-7)*2) -> 44563 | B3: 1
A4: =A3+7 -> 44570 | B4: 2
A5: =A4+7 -> 44577 | B5: 3
A6: =A5+7 -> 44584 | B6: 4
A7: =A6+7 -> 44591 | B7: 5
A8: =A7+7 -> 44598 | B8: 6
A9: =A8+7 -> 44605 | B9: 7
A10: =A9+7 -> 44612 | B10: 8
A11: =A10+7 -> 44619 | B11: 9
A12: =A11+7 -> 44626 | B12: 10
A13: =A12+7 -> 44633 | B13: 11
A14: =A13+7 -> 44640 | B14: 12
A15: =A14+7 -> 44647 | B15: 13
... A56: =A55+7 -> 44934 | B56: 54
A57: Semana
A59: Dia | B59: S
A60: =OvoTotal!I3 -> 44562 | B60: =WEEKNUM(A60,2) -> 1 | C60: 0.1535 | D60: 72096 | E60: 82656 | H60: 33120 | I60: 16224 | L60: 28308
A61: =OvoTotal!I4 -> 44563 | B61: =WEEKNUM(A61,2) -> 1 | C61: 0.1535 | D61: 50832 | E61: 51168 | H61: 27000 | I61: 18720 | L61: 31320
A62: =OvoTotal!I5 -> 44564 | B62: =WEEKNUM(A62,2) -> 2 | C62: 0.1535 | D62: 18504 | E62: 20952 | H62: 25200 | I62: 21240 | L62: 23760
A63: =OvoTotal!I6 -> 44565 | B63: =WEEKNUM(A63,2) -> 2 | C63: 0.1535 | D63: 31776 | E63: 28224 | H63: 32064 | I63: 17856 | L63: 22320
A64: =OvoTotal!I7 -> 44566 | B64: =WEEKNUM(A64,2) -> 2 | C64: 0.1535 | D64: 35040 | E64: 35040 | H64: 51456 | I64: 32064 | L64: 23400
A65: =OvoTotal!I8 -> 44567 | B65: =WEEKNUM(A65,2) -> 2 | C65: 0.1535 | D65: 44928 | E65: 41472 | H65: 29306 | I65: 18144 | L65: 11160
B66: =SUBTOTAL(1,B60:B65) -> 1.6666667
A67: =OvoTotal!I9 -> 44568 | B67: =WEEKNUM(A67,2) -> 2 | C67: 0.1535 | D67: 35616 | E67: 31776 | H67: 40910 | I67: 34272 | L67: 12600
A68: =OvoTotal!I10 -> 44569 | B68: =WEEKNUM(A68,2) -> 2 | C68: 0.1535 | D68: 42048 | E68: 38592 | H68: 35520 | I68: 27264 | L68: 13320
A69: =OvoTotal!I11 -> 44570 | B69: =WEEKNUM(A69,2) -> 2 | C69: 0.1535 | D69: 45600 | E69: 45312 | H69: 38592 | I69: 28032 | L69: 10080
A70: =OvoTotal!I12 -> 44571 | B70: =WEEKNUM(A70,2) -> 3 | C70: 0.1535 | D70: 28032 | E70: 28032 | H70: 35986 | I70: 28960
A71: =OvoTotal!I13 -> 44572 | B71: =WEEKNUM(A71,2) -> 3 | C71: 0.1535 | D71: 28320 | E71: 28416 | H71: 35328 | I71: 28320
A72: =OvoTotal!I14 -> 44573 | B72: =WEEKNUM(A72,2) -> 3 | C72: 0.1535 | D72: 20736 | E72: 24192 | H72: 37152 | I72: 29760
A73: =OvoTotal!I15 -> 44574 | B73: =WEEKNUM(A73,2) -> 3 | C73: 0.1535 | D73: 25560 | E73: 27000 | H73: 39264 | I73: 32256
B74: =SUBTOTAL(1,B67:B73) -> 2.5714286
A75: =OvoTotal!I16 -> 44575 | B75: =WEEKNUM(A75,2) -> 3 | C75: 0.1535 | D75: 40680 | E75: 43560 | H75: 41760 | I75: 25200
A76: =OvoTotal!I17 -> 44576 | B76: =WEEKNUM(A76,2) -> 3 | C76: 0.1535 | D76: 33768 | E76: 34104 | H76: 41760 | I76: 21600
A77: =OvoTotal!I18 -> 44577 | B77: =WEEKNUM(A77,2) -> 3 | C77: 0.1535 | D77: 54072 | E77: 47016 | H77: 40680 | I77: 26640
A78: =OvoTotal!I19 -> 44578 | B78: =WEEKNUM(A78,2) -> 4 | C78: 0.1535 | D78: 45780 | E78: 45780 | H78: 36096 | I78: 28224
A79: =OvoTotal!I20 -> 44579 | B79: =WEEKNUM(A79,2) -> 4 | C79: 0.1535 | D79: 36576 | E79: 36456 | H79: 30528 | I79: 27936
A80: =OvoTotal!I21 -> 44580 | B80: =WEEKNUM(A80,2) -> 4 | C80: 0.1535 | D80: 36960 | E80: 36960 | H80: 42432 | I80: 36480
A81: =OvoTotal!I22 -> 44581 | B81: =WEEKNUM(A81,2) -> 4 | C81: 0.1535 | D81: 42000 | E81: 37548 | H81: 38976 | I81: 30720
...

Sheet Outros
C1: =OvoTotal!J1 -> AA | D1: =OvoTotal!K1 -> BB | E1: =OvoTotal!L1 -> CC | F1: =OvoTotal!M1 -> DD | G1: =OvoTotal!N1 -> EE | H1: =OvoTotal!O1 -> FF | I1: =OvoTotal!P1 -> GG | J1: =OvoTotal!Q1 -> HH | ... AG1: =OvoTotal!AN1 -> EEE
A2: $ | C2: =OvoTotal!J2 -> SJ F1 A 221 R | D2: =OvoTotal!K2 -> SJ F1 B 321 R | E2: =OvoTotal!L2 -> SJ F1 A 222 R | F2: =OvoTotal!M2 -> SJ F1 B 322 R | G2: =OvoTotal!N2 -> SJ F2 A 421 R | H2: =OvoTotal!O2 -> SJ F2 B 521 R | I2: =OvoTotal!P2 -> SJ F2 A 422 R | J2: =OvoTotal!Q2 -> SJ F2 B 522 R | ... AG2: =OvoTotal!AN2 -> AAA 1 001
A3: =Produção!A3 -> 44563 | B3: 1
A4: =A3+7 -> 44570 | B4: 2
A5: =A4+7 -> 44577 | B5: 3
A6: =A5+7 -> 44584 | B6: 4
A7: =A6+7 -> 44591 | B7: 5
A8: =A7+7 -> 44598 | B8: 6
A9: =A8+7 -> 44605 | B9: 7
A10: =A9+7 -> 44612 | B10: 8
A11: =A10+7 -> 44619 | B11: 9 | K11: 325886.15
A12: =A11+7 -> 44626 | B12: 10
A13: =A12+7 -> 44633 | B13: 11
A14: =A13+7 -> 44640 | B14: 12
A15: =A14+7 -> 44647 | B15: 13
A16: =A15+7 -> 44654 | B16: 14
A17: =A16+7 -> 44661 | B17: 15
A18: =A17+7 -> 44668 | B18: 16
A19: =A18+7 -> 44675 | B19: 17
A20: =A19+7 -> 44682 | B20: 18
A21: =A20+7 -> 44689 | B21: 19
A22: =A21+7 -> 44696 | B22: 20
A23: =A22+7 -> 44703 | B23: 21
A24: =A23+7 -> 44710 | B24: 22 | M24: 250769
A25: =A24+7 -> 44717 | B25: 23
A26: =A25+7 -> 44724 | B26: 24
A27: =A26+7 -> 44731 | B27: 25
A28: =A27+7 -> 44738 | B28: 26
A29: =A28+7 -> 44745 | B29: 27
A30: =A29+7 -> 44752 | B30: 28
A31: =A30+7 -> 44759 | B31: 29
A32: =A31+7 -> 44766 | B32: 30
A33: =A32+7 -> 44773 | B33: 31
A34: =A33+7 -> 44780 | B34: 32
A35: =A34+7 -> 44787 | B35: 33
A36: =A35+7 -> 44794 | B36: 34
... A56: =A55+7 -> 44934 | B56: 54

Sheet Dados
A1: Indicador | B1: Núcleo/Lote | C1: 1 | D1: 2 | E1: 3 | F1: 4 | G1: 5 | H1: 6 | I1: 7 | J1: 8 | K1: 9 | L1: 10 | M1: 11 | N1: 12 | O1: 13 | P1: 14 | Q1: 15 | R1: 16 | S1: 17 | T1: 18 | U1: 19 | V1: 20 | W1: 21 | X1: 22 | Y1: 23 | Z1: 24 | AA1: 25 | AB1: 26 | AC1: 27 | AD1: 28 | AE1: 29 | AF1: 30 | AG1: 31 | AH1: 32 | AI1: 33 | AJ1: 34 | AK1: 35 | AL1: 36 | AM1: 37 | AN1: 38 | AO1: 39 | AP1: 40 | AQ1: 41 | AR1: 42 | AS1: 43 | AT1: 44 | AU1: 45 | AV1: 46 | AW1: 47 | AX1: 48 | AY1: 49 | AZ1: 50 | BA1: 51 | BB1: 52 | BC1: 53 | BD1: 54 | BF1: 43466 | BG1: =EOMONTH(BF1,0)+1 -> 43497 | BH1: =EOMONTH(BG1,0)+1 -> 43525 | BI1: =EOMONTH(BH1,0)+1 -> 43556 | BJ1: =EOMONTH(BI1,0)+1 -> 43586 | BK1: =EOMONTH(BJ1,0)+1 -> 43617 | BL1: =EOMONTH(BK1,0)+1 -> 43647 | BM1: =EOMONTH(BL1,0)+1 -> 43678 | BN1: =EOMONTH(BM1,0)+1 -> 43709 | ... BQ1: =EOMONTH(BP1,0)+1 -> 43800
A2: Ovos Tot Prev | B2: =OvoTotal!J2 -> SJ F1 A 221 R | C2: =SUMIFS(OvoTotal!J:J,OvoTotal!$I:$I,"<="&EOMONTH(OvoTotal!$I$3+360,0),OvoTotal!$AW:$AW,Dados!$C1) -> 40099.213 | D2: =SUMIFS(OvoTotal!J:J,OvoTotal!$I:$I,"<="&EOMONTH(OvoTotal!$I$3+360,0),OvoTotal!$AW:$AW,Dados!$D1) -> 277854.78 | E2: =SUMIFS(OvoTotal!J:J,OvoTotal!$I:$I,"<="&EOMONTH(OvoTotal!$I$3+360,0),OvoTotal!$AW:$AW,Dados!$E1) -> 273773.6 | F2: =SUMIFS(OvoTotal!J:J,OvoTotal!$I:$I,"<="&EOMONTH(OvoTotal!$I$3+360,0),OvoTotal!$AW:$AW,Dados!$F1) -> 269708.36 | G2: =SUMIFS(OvoTotal!J:J,OvoTotal!$I:$I,"<="&EOMONTH(OvoTotal!$I$3+360,0),OvoTotal!$AW:$AW,Dados!$G1) -> 265658.99 | H2: =SUMIFS(OvoTotal!J:J,OvoTotal!$I:$I,"<="&EOMONTH(OvoTotal!$I$3+360,0),OvoTotal!$AW:$AW,Dados!$H1) -> 261625.46 | I2: =SUMIFS(OvoTotal!J:J,OvoTotal!$I:$I,"<="&EOMONTH(OvoTotal!$I$3+360,0),OvoTotal!$AW:$AW,Dados!$I1) -> 257607.71 | J2: =SUMIFS(OvoTotal!J:J,OvoTotal!$I:$I,"<="&EOMONTH(OvoTotal!$I$3+360,0),OvoTotal!$AW:$AW,Dados!$J1) -> 253605.69 | K2: =SUMIFS(OvoTotal!J:J,OvoTotal!$I:$I,"<="&EOMONTH(OvoTotal!$I$3+360,0),OvoTotal!$AW:$AW,Dados!$K1) -> 249619.36 | L2: =SUMIFS(OvoTotal!J:J,OvoTotal!$I:$I,"<="&EOMONTH(OvoTotal!$I$3+360,0),OvoTotal!$AW:$AW,Dados!$L1) -> 245648.68 | M2: =SUMIFS(OvoTotal!J:J,OvoTotal!$I:$I,"<="&EOMONTH(OvoTotal!$I$3+360,0),OvoTotal!$AW:$AW,Dados!$M1) -> 241693.58 | N2: =SUMIFS(OvoTotal!J:J,OvoTotal!$I:$I,"<="&EOMONTH(OvoTotal!$I$3+360,0),OvoTotal!$AW:$AW,Dados!$N1) -> 237754.02 | O2: =SUMIFS(OvoTotal!J:J,OvoTotal!$I:$I,"<="&EOMONTH(OvoTotal!$I$3+360,0),OvoTotal!$AW:$AW,Dados!$O1) -> 233829.96 | P2: =SUMIFS(OvoTotal!J:J,OvoTotal!$I:$I,"<="&EOMONTH(OvoTotal!$I$3+360,0),OvoTotal!$AW:$AW,Dados!$P1) -> 229921.35 | Q2: =SUMIFS(OvoTotal!J:J,OvoTotal!$I:$I,"<="&EOMONTH(OvoTotal!$I$3+360,0),OvoTotal!$AW:$AW,Dados!$Q1) -> 226028.13 | R2: =SUMIFS(OvoTotal!J:J,OvoTotal!$I:$I,"<="&EOMONTH(OvoTotal!$I$3+360,0),OvoTotal!$AW:$AW,Dados!$R1) -> 222150.27 | S2: =SUMIFS(OvoTotal!J:J,OvoTotal!$I:$I,"<="&EOMONTH(OvoTotal!$I$3+360,0),OvoTotal!$AW:$AW,Dados!$S1) -> 218287.71 | T2: =SUMIFS(OvoTotal!J:J,OvoTotal!$I:$I,"<="&EOMONTH(OvoTotal!$I$3+360,0),OvoTotal!$AW:$AW,Dados!$T1) -> 214440.41 | U2: =SUMIFS(OvoTotal!J:J,OvoTotal!$I:$I,"<="&EOMONTH(OvoTotal!$I$3+360,0),OvoTotal!$AW:$AW,Dados!$U1) -> 210608.32 | V2: =SUMIFS(OvoTotal!J:J,OvoTotal!$I:$I,"<="&EOMONTH(OvoTotal!$I$3+360,0),OvoTotal!$AW:$AW,Dados!$V1) -> 206791.39 | W2: =SUMIFS(OvoTotal!J:J,OvoTotal!$I:$I,"<="&EOMONTH(OvoTotal!$I$3+360,0),OvoTotal!$AW:$AW,Dados!$W1) -> 202989.58 | X2: =SUMIFS(OvoTotal!J:J,OvoTotal!$I:$I,"<="&EOMONTH(OvoTotal!$I$3+360,0),OvoTotal!$AW:$AW,Dados!$X1) -> 199202.84 | Y2: =SUMIFS(OvoTotal!J:J,OvoTotal!$I:$I,"<="&EOMONTH(OvoTotal!$I$3+360,0),OvoTotal!$AW:$AW,Dados!$Y1) -> 195431.12 | Z2: =SUMIFS(OvoTotal!J:J,OvoTotal!$I:$I,"<="&EOMONTH(OvoTotal!$I$3+360,0),OvoTotal!$AW:$AW,Dados!$Z1) -> 191674.38 | AA2: =SUMIFS(OvoTotal!J:J,OvoTotal!$I:$I,"<="&EOMONTH(OvoTotal!$I$3+360,0),OvoTotal!$AW:$AW,Dados!$AA1) -> 187932.57 | AB2: =SUMIFS(OvoTotal!J:J,OvoTotal!$I:$I,"<="&EOMONTH(OvoTotal!$I$3+360,0),OvoTotal!$AW:$AW,Dados!$AB1) -> 184205.65 | AC2: =SUMIFS(OvoTotal!J:J,OvoTotal!$I:$I,"<="&EOMONTH(OvoTotal!$I$3+360,0),OvoTotal!$AW:$AW,Dados!$AC1) -> 180493.56 | AD2: =SUMIFS(OvoTotal!J:J,OvoTotal!$I:$I,"<="&EOMONTH(OvoTotal!$I$3+360,0),OvoTotal!$AW:$AW,Dados!$AD1) -> 176796.26 | AE2: =SUMIFS(OvoTotal!J:J,OvoTotal!$I:$I,"<="&EOMONTH(OvoTotal!$I$3+360,0),OvoTotal!$AW:$AW,Dados!$AE1) -> 173113.72 | AF2: =SUMIFS(OvoTotal!J:J,OvoTotal!$I:$I,"<="&EOMONTH(OvoTotal!$I$3+360,0),OvoTotal!$AW:$AW,Dados!$AF1) -> 169445.87 | AG2: =SUMIFS(OvoTotal!J:J,OvoTotal!$I:$I,"<="&EOMONTH(OvoTotal!$I$3+360,0),OvoTotal!$AW:$AW,Dados!$AG1) -> 163438.38 | AH2: =SUMIFS(OvoTotal!J:J,OvoTotal!$I:$I,"<="&EOMONTH(OvoTotal!$I$3+360,0),OvoTotal!$AW:$AW,Dados!$AH1) -> 46095.584 | AI2: =SUMIFS(OvoTotal!J:J,OvoTotal!$I:$I,"<="&EOMONTH(OvoTotal!$I$3+360,0),OvoTotal!$AW:$AW,Dados!$AI1) -> 0 | AJ2: =SUMIFS(OvoTotal!J:J,OvoTotal!$I:$I,"<="&EOMONTH(OvoTotal!$I$3+360,0),OvoTotal!$AW:$AW,Dados!$AJ1) -> 0 | AK2: =SUMIFS(OvoTotal!J:J,OvoTotal!$I:$I,"<="&EOMONTH(OvoTotal!$I$3+360,0),OvoTotal!$AW:$AW,Dados!$AK1) -> 0 | AL2: =SUMIFS(OvoTotal!J:J,OvoTotal!$I:$I,"<="&EOMONTH(OvoTotal!$I$3+360,0),OvoTotal!$AW:$AW,Dados!$AL1) -> 0 | AM2: =SUMIFS(OvoTotal!J:J,OvoTotal!$I:$I,"<="&EOMONTH(OvoTotal!$I$3+360,0),OvoTotal!$AW:$AW,Dados!$AM1) -> 0 | AN2: =SUMIFS(OvoTotal!J:J,OvoTotal!$I:$I,"<="&EOMONTH(OvoTotal!$I$3+360,0),OvoTotal!$AW:$AW,Dados!$AN1) -> 0 | AO2: =SUMIFS(OvoTotal!J:J,OvoTotal!$I:$I,"<="&EOMONTH(OvoTotal!$I$3+360,0),OvoTotal!$AW:$AW,Dados!$AO1) -> 0 | AP2: =SUMIFS(OvoTotal!J:J,OvoTotal!$I:$I,"<="&EOMONTH(OvoTotal!$I$3+360,0),OvoTotal!$AW:$AW,Dados!$AP1) -> 0 | AQ2: =SUMIFS(OvoTotal!J:J,OvoTotal!$I:$I,"<="&EOMONTH(OvoTotal!$I$3+360,0),OvoTotal!$AW:$AW,Dados!$AQ1) -> 0 | AR2: =SUMIFS(OvoTotal!J:J,OvoTotal!$I:$I,"<="&EOMONTH(OvoTotal!$I$3+360,0),OvoTotal!$AW:$AW,Dados!$AR1) -> 0 | AS2: =SUMIFS(OvoTotal!J:J,OvoTotal!$I:$I,"<="&EOMONTH(OvoTotal!$I$3+360,0),OvoTotal!$AW:$AW,Dados!$AS1) -> 0 | AT2: =SUMIFS(OvoTotal!J:J,OvoTotal!$I:$I,"<="&EOMONTH(OvoTotal!$I$3+360,0),OvoTotal!$AW:$AW,Dados!$AT1) -> 0 | AU2: =SUMIFS(OvoTotal!J:J,OvoTotal!$I:$I,"<="&EOMONTH(OvoTotal!$I$3+360,0),OvoTotal!$AW:$AW,Dados!$AU1) -> 0 | AV2: =SUMIFS(OvoTotal!J:J,OvoTotal!$I:$I,"<="&EOMONTH(OvoTotal!$I$3+360,0),OvoTotal!$AW:$AW,Dados!$AV1) -> 0 | AW2: =SUMIFS(OvoTotal!J:J,OvoTotal!$I:$I,"<="&EOMONTH(OvoTotal!$I$3+360,0),OvoTotal!$AW:$AW,Dados!$AW1) -> 0 | AX2: =SUMIFS(OvoTotal!J:J,OvoTotal!$I:$I,"<="&EOMONTH(OvoTotal!$I$3+360,0),OvoTotal!$AW:$AW,Dados!$AX1) -> 0 | AY2: =SUMIFS(OvoTotal!J:J,OvoTotal!$I:$I,"<="&EOMONTH(OvoTotal!$I$3+360,0),OvoTotal!$AW:$AW,Dados!$AY1) -> 0 | AZ2: =SUMIFS(OvoTotal!J:J,OvoTotal!$I:$I,"<="&EOMONTH(OvoTotal!$I$3+360,0),OvoTotal!$AW:$AW,Dados!$AZ1) -> 0 | BA2: =SUMIFS(OvoTotal!J:J,OvoTotal!$I:$I,"<="&EOMONTH(OvoTotal!$I$3+360,0),OvoTotal!$AW:$AW,Dados!$BA1) -> 0 | BB2: =SUMIFS(OvoTotal!J:J,OvoTotal!$I:$I,"<="&EOMONTH(OvoTotal!$I$3+360,0),OvoTotal!$AW:$AW,Dados!$BB1) -> 0 | BC2: =SUMIFS(OvoTotal!J:J,OvoTotal!$I:$I,"<="&EOMONTH(OvoTotal!$I$3+360,0),OvoTotal!$AW:$AW,Dados!$BC1) -> 0 | BD2: =SUMIFS(OvoTotal!J:J,OvoTotal!$I:$I,"<="&EOMONTH(OvoTotal!$I$3+360,0),OvoTotal!$AW:$AW,Dados!$BD1) -> 0 | BF2: =SUMIFS(OvoTotal!J:J,OvoTotal!$I:$I,">="&BF1,OvoTotal!$I:$I,"<="&EOMONTH($BF1,0)) -> 0 | BG2: =SUMIFS(OvoTotal!J:J,OvoTotal!$I:$I,">="&BG1,OvoTotal!$I:$I,"<="&EOMONTH($BG1,0)) -> 0 | BH2: =SUMIFS(OvoTotal!J:J,OvoTotal!$I:$I,">="&BH1,OvoTotal!$I:$I,"<="&EOMONTH($BH1,0)) -> 0 | BI2: =SUMIFS(OvoTotal!J:J,OvoTotal!$I:$I,">="&BI1,OvoTotal!$I:$I,"<="&EOMONTH($BI1,0)) -> 0 | BJ2: =SUMIFS(OvoTotal!J:J,OvoTotal!$I:$I,">="&BJ1,OvoTotal!$I:$I,"<="&EOMONTH($BJ1,0)) -> 0 | BK2: =SUMIFS(OvoTotal!J:J,OvoTotal!$I:$I,">="&BK1,OvoTotal!$I:$I,"<="&EOMONTH($BK1,0)) -> 0 | BL2: =SUMIFS(OvoTotal!J:J,OvoTotal!$I:$I,">="&BL1,OvoTotal!$I:$I,"<="&EOMONTH($BL1,0)) -> 0 | BM2: =SUMIFS(OvoTotal!J:J,OvoTotal!$I:$I,">="&BM1,OvoTotal!$I:$I,"<="&EOMONTH($BM1,0)) -> 0 | BN2: =SUMIFS(OvoTotal!J:J,OvoTotal!$I:$I,">="&BN1,OvoTotal!$I:$I,"<="&EOMONTH($BN1,0)) -> 0 | BO2: =SUMIFS(OvoTotal!J:J,OvoTotal!$I:$I,">="&BO1,OvoTotal!$I:$I,"<="&EOMONTH($BO1,0)) -> 0 | BP2: =SUMIFS(OvoTotal!J:J,OvoTotal!$I:$I,">="&BP1,OvoTotal!$I:$I,"<="&EOMONTH($BP1,0)) -> 0 | BQ2: =SUMIFS(OvoTotal!J:J,OvoTotal!$I:$I,">="&BQ1,OvoTotal!$I:$I,"<="&EOMONTH($BQ1,0)) -> 0
